[2025-06-28T00:45:25.414+0000] {local_task_job_runner.py:120} INFO - ::group::Pre task execution logs
[2025-06-28T00:45:25.431+0000] {taskinstance.py:2076} INFO - Dependencies all met for dep_context=non-requeueable deps ti=<TaskInstance: etl_reddit_pipeline.reddit_extraction scheduled__2025-06-27T00:00:00+00:00 [queued]>
[2025-06-28T00:45:25.435+0000] {taskinstance.py:2076} INFO - Dependencies all met for dep_context=requeueable deps ti=<TaskInstance: etl_reddit_pipeline.reddit_extraction scheduled__2025-06-27T00:00:00+00:00 [queued]>
[2025-06-28T00:45:25.436+0000] {taskinstance.py:2306} INFO - Starting attempt 1 of 1
[2025-06-28T00:45:25.442+0000] {taskinstance.py:2330} INFO - Executing <Task(PythonOperator): reddit_extraction> on 2025-06-27 00:00:00+00:00
[2025-06-28T00:45:25.449+0000] {standard_task_runner.py:63} INFO - Started process 66 to run task
[2025-06-28T00:45:25.454+0000] {standard_task_runner.py:90} INFO - Running: ['airflow', 'tasks', 'run', 'etl_reddit_pipeline', 'reddit_extraction', 'scheduled__2025-06-27T00:00:00+00:00', '--job-id', '18', '--raw', '--subdir', 'DAGS_FOLDER/reddit_dag.py', '--cfg-path', '/tmp/tmpgwj_fphc']
[2025-06-28T00:45:25.470+0000] {standard_task_runner.py:91} INFO - Job 18: Subtask reddit_extraction
[2025-06-28T00:45:25.687+0000] {task_command.py:426} INFO - Running <TaskInstance: etl_reddit_pipeline.reddit_extraction scheduled__2025-06-27T00:00:00+00:00 [running]> on host 0e28f0019673
[2025-06-28T00:45:25.951+0000] {taskinstance.py:2648} INFO - Exporting env vars: AIRFLOW_CTX_DAG_OWNER='naspuka' AIRFLOW_CTX_DAG_ID='etl_reddit_pipeline' AIRFLOW_CTX_TASK_ID='reddit_extraction' AIRFLOW_CTX_EXECUTION_DATE='2025-06-27T00:00:00+00:00' AIRFLOW_CTX_TRY_NUMBER='1' AIRFLOW_CTX_DAG_RUN_ID='scheduled__2025-06-27T00:00:00+00:00'
[2025-06-28T00:45:25.960+0000] {taskinstance.py:430} INFO - ::endgroup::
[2025-06-28T00:45:26.129+0000] {logging_mixin.py:188} INFO - connected to reddit
[2025-06-28T00:45:26.137+0000] {sessions.py:161} WARNING - Retrying due to ConnectionError(MaxRetryError('HTTPSConnectionPool(host=\'www.reddit.com\', port=443): Max retries exceeded with url: /api/v1/access_token (Caused by NameResolutionError("<urllib3.connection.HTTPSConnection object at 0xffff9c073970>: Failed to resolve \'www.reddit.com\' ([Errno -2] Name or service not known)"))')) status: GET https://oauth.reddit.com/r/dataengineering/top
[2025-06-28T00:45:26.602+0000] {sessions.py:161} WARNING - Retrying due to ConnectionError(MaxRetryError('HTTPSConnectionPool(host=\'www.reddit.com\', port=443): Max retries exceeded with url: /api/v1/access_token (Caused by NameResolutionError("<urllib3.connection.HTTPSConnection object at 0xffff9c0735b0>: Failed to resolve \'www.reddit.com\' ([Errno -2] Name or service not known)"))')) status: GET https://oauth.reddit.com/r/dataengineering/top
[2025-06-28T00:45:29.293+0000] {taskinstance.py:441} INFO - ::group::Post task execution logs
[2025-06-28T00:45:29.333+0000] {taskinstance.py:2905} ERROR - Task failed with exception
Traceback (most recent call last):
  File "/home/airflow/.local/lib/python3.9/site-packages/airflow/models/taskinstance.py", line 465, in _execute_task
    result = _execute_callable(context=context, **execute_callable_kwargs)
  File "/home/airflow/.local/lib/python3.9/site-packages/airflow/models/taskinstance.py", line 432, in _execute_callable
    return execute_callable(context=context, **execute_callable_kwargs)
  File "/home/airflow/.local/lib/python3.9/site-packages/airflow/models/baseoperator.py", line 400, in wrapper
    return func(self, *args, **kwargs)
  File "/home/airflow/.local/lib/python3.9/site-packages/airflow/operators/python.py", line 235, in execute
    return_value = self.execute_callable()
  File "/home/airflow/.local/lib/python3.9/site-packages/airflow/operators/python.py", line 252, in execute_callable
    return self.python_callable(*self.op_args, **self.op_kwargs)
  File "/opt/airflow/pipelines/reddit_pipeline.py", line 9, in reddit_pipeline
    posts = extract_posts(instance, subreddit, time_filter, limit)
  File "/opt/airflow/etls/reddit_etl.py", line 25, in extract_posts
    for post in posts:
  File "/home/airflow/.local/lib/python3.9/site-packages/praw/models/listing/generator.py", line 66, in __next__
    self._next_batch()
  File "/home/airflow/.local/lib/python3.9/site-packages/praw/models/listing/generator.py", line 90, in _next_batch
    self._listing = self._reddit.get(self.url, params=self.params)
  File "/home/airflow/.local/lib/python3.9/site-packages/praw/util/deprecate_args.py", line 46, in wrapped
    return func(**dict(zip(_old_args, args)), **kwargs)
  File "/home/airflow/.local/lib/python3.9/site-packages/praw/reddit.py", line 731, in get
    return self._objectify_request(method="GET", params=params, path=path)
  File "/home/airflow/.local/lib/python3.9/site-packages/praw/reddit.py", line 514, in _objectify_request
    self.request(
  File "/home/airflow/.local/lib/python3.9/site-packages/praw/util/deprecate_args.py", line 46, in wrapped
    return func(**dict(zip(_old_args, args)), **kwargs)
  File "/home/airflow/.local/lib/python3.9/site-packages/praw/reddit.py", line 963, in request
    return self._core.request(
  File "/home/airflow/.local/lib/python3.9/site-packages/prawcore/sessions.py", line 328, in request
    return self._request_with_retries(
  File "/home/airflow/.local/lib/python3.9/site-packages/prawcore/sessions.py", line 254, in _request_with_retries
    return self._do_retry(
  File "/home/airflow/.local/lib/python3.9/site-packages/prawcore/sessions.py", line 162, in _do_retry
    return self._request_with_retries(
  File "/home/airflow/.local/lib/python3.9/site-packages/prawcore/sessions.py", line 254, in _request_with_retries
    return self._do_retry(
  File "/home/airflow/.local/lib/python3.9/site-packages/prawcore/sessions.py", line 162, in _do_retry
    return self._request_with_retries(
  File "/home/airflow/.local/lib/python3.9/site-packages/prawcore/sessions.py", line 234, in _request_with_retries
    response, saved_exception = self._make_request(
  File "/home/airflow/.local/lib/python3.9/site-packages/prawcore/sessions.py", line 186, in _make_request
    response = self._rate_limiter.call(
  File "/home/airflow/.local/lib/python3.9/site-packages/prawcore/rate_limit.py", line 46, in call
    kwargs["headers"] = set_header_callback()
  File "/home/airflow/.local/lib/python3.9/site-packages/prawcore/sessions.py", line 282, in _set_header_callback
    self._authorizer.refresh()
  File "/home/airflow/.local/lib/python3.9/site-packages/prawcore/auth.py", line 378, in refresh
    self._request_token(grant_type="client_credentials", **additional_kwargs)
  File "/home/airflow/.local/lib/python3.9/site-packages/prawcore/auth.py", line 155, in _request_token
    response = self._authenticator._post(url=url, **data)
  File "/home/airflow/.local/lib/python3.9/site-packages/prawcore/auth.py", line 51, in _post
    response = self._requestor.request(
  File "/home/airflow/.local/lib/python3.9/site-packages/prawcore/requestor.py", line 70, in request
    raise RequestException(exc, args, kwargs) from None
prawcore.exceptions.RequestException: error with request HTTPSConnectionPool(host='www.reddit.com', port=443): Max retries exceeded with url: /api/v1/access_token (Caused by NameResolutionError("<urllib3.connection.HTTPSConnection object at 0xffff9c0738e0>: Failed to resolve 'www.reddit.com' ([Errno -2] Name or service not known)"))
[2025-06-28T00:45:29.472+0000] {taskinstance.py:1206} INFO - Marking task as FAILED. dag_id=etl_reddit_pipeline, task_id=reddit_extraction, run_id=scheduled__2025-06-27T00:00:00+00:00, execution_date=20250627T000000, start_date=20250628T004525, end_date=20250628T004529
[2025-06-28T00:45:29.543+0000] {standard_task_runner.py:110} ERROR - Failed to execute job 18 for task reddit_extraction (error with request HTTPSConnectionPool(host='www.reddit.com', port=443): Max retries exceeded with url: /api/v1/access_token (Caused by NameResolutionError("<urllib3.connection.HTTPSConnection object at 0xffff9c0738e0>: Failed to resolve 'www.reddit.com' ([Errno -2] Name or service not known)")); 66)
[2025-06-28T00:45:29.584+0000] {local_task_job_runner.py:240} INFO - Task exited with return code 1
[2025-06-28T00:45:29.632+0000] {taskinstance.py:3498} INFO - 0 downstream tasks scheduled from follow-on schedule check
[2025-06-28T00:45:29.634+0000] {local_task_job_runner.py:222} INFO - ::endgroup::
