[2025-06-29T09:57:51.061+0000] {local_task_job_runner.py:120} INFO - ::group::Pre task execution logs
[2025-06-29T09:57:51.125+0000] {taskinstance.py:2076} INFO - Dependencies all met for dep_context=non-requeueable deps ti=<TaskInstance: etl_reddit_pipeline.s3_upload manual__2025-06-29T09:57:44.756224+00:00 [queued]>
[2025-06-29T09:57:51.136+0000] {taskinstance.py:2076} INFO - Dependencies all met for dep_context=requeueable deps ti=<TaskInstance: etl_reddit_pipeline.s3_upload manual__2025-06-29T09:57:44.756224+00:00 [queued]>
[2025-06-29T09:57:51.136+0000] {taskinstance.py:2306} INFO - Starting attempt 1 of 1
[2025-06-29T09:57:51.162+0000] {taskinstance.py:2330} INFO - Executing <Task(PythonOperator): s3_upload> on 2025-06-29 09:57:44.756224+00:00
[2025-06-29T09:57:51.182+0000] {standard_task_runner.py:63} INFO - Started process 65 to run task
[2025-06-29T09:57:51.195+0000] {standard_task_runner.py:90} INFO - Running: ['airflow', 'tasks', 'run', 'etl_reddit_pipeline', 's3_upload', 'manual__2025-06-29T09:57:44.756224+00:00', '--job-id', '7', '--raw', '--subdir', 'DAGS_FOLDER/reddit_dag.py', '--cfg-path', '/tmp/tmpsj12wymf']
[2025-06-29T09:57:51.202+0000] {standard_task_runner.py:91} INFO - Job 7: Subtask s3_upload
[2025-06-29T09:57:51.312+0000] {task_command.py:426} INFO - Running <TaskInstance: etl_reddit_pipeline.s3_upload manual__2025-06-29T09:57:44.756224+00:00 [running]> on host b1203407efc8
[2025-06-29T09:57:51.407+0000] {taskinstance.py:2648} INFO - Exporting env vars: AIRFLOW_CTX_DAG_OWNER='naspuka' AIRFLOW_CTX_DAG_ID='etl_reddit_pipeline' AIRFLOW_CTX_TASK_ID='s3_upload' AIRFLOW_CTX_EXECUTION_DATE='2025-06-29T09:57:44.756224+00:00' AIRFLOW_CTX_TRY_NUMBER='1' AIRFLOW_CTX_DAG_RUN_ID='manual__2025-06-29T09:57:44.756224+00:00'
[2025-06-29T09:57:51.412+0000] {taskinstance.py:430} INFO - ::endgroup::
[2025-06-29T09:57:53.547+0000] {logging_mixin.py:188} INFO - The AWS Access Key Id you provided does not exist in our records.
[2025-06-29T09:57:53.685+0000] {taskinstance.py:441} INFO - ::group::Post task execution logs
[2025-06-29T09:57:53.687+0000] {taskinstance.py:2905} ERROR - Task failed with exception
Traceback (most recent call last):
  File "/home/airflow/.local/lib/python3.9/site-packages/s3fs/core.py", line 755, in _lsdir
    async for c in self._iterdir(
  File "/home/airflow/.local/lib/python3.9/site-packages/s3fs/core.py", line 805, in _iterdir
    async for i in it:
  File "/home/airflow/.local/lib/python3.9/site-packages/aiobotocore/paginate.py", line 39, in __anext__
    response = await self._make_request(current_kwargs)
  File "/home/airflow/.local/lib/python3.9/site-packages/aiobotocore/context.py", line 36, in wrapper
    return await func(*args, **kwargs)
  File "/home/airflow/.local/lib/python3.9/site-packages/aiobotocore/paginate.py", line 19, in _make_request
    return await self._method(**current_kwargs)
  File "/home/airflow/.local/lib/python3.9/site-packages/aiobotocore/context.py", line 36, in wrapper
    return await func(*args, **kwargs)
  File "/home/airflow/.local/lib/python3.9/site-packages/aiobotocore/client.py", line 415, in _make_api_call
    raise error_class(parsed_response, operation_name)
botocore.exceptions.ClientError: An error occurred (InvalidAccessKeyId) when calling the ListObjectsV2 operation: The AWS Access Key Id you provided does not exist in our records.

The above exception was the direct cause of the following exception:

Traceback (most recent call last):
  File "/home/airflow/.local/lib/python3.9/site-packages/airflow/models/taskinstance.py", line 465, in _execute_task
    result = _execute_callable(context=context, **execute_callable_kwargs)
  File "/home/airflow/.local/lib/python3.9/site-packages/airflow/models/taskinstance.py", line 432, in _execute_callable
    return execute_callable(context=context, **execute_callable_kwargs)
  File "/home/airflow/.local/lib/python3.9/site-packages/airflow/models/baseoperator.py", line 400, in wrapper
    return func(self, *args, **kwargs)
  File "/home/airflow/.local/lib/python3.9/site-packages/airflow/operators/python.py", line 235, in execute
    return_value = self.execute_callable()
  File "/home/airflow/.local/lib/python3.9/site-packages/airflow/operators/python.py", line 252, in execute_callable
    return self.python_callable(*self.op_args, **self.op_kwargs)
  File "/opt/airflow/pipelines/aws_s3_pipeline.py", line 10, in upload_s3_pipeline
    upload_to_s3(s3, file_path, AWS_BUCKET_NAME, file_path.split('/')[-1])
  File "/opt/airflow/etls/aws_etl.py", line 26, in upload_to_s3
    s3.put(file_path, bucket+'/raw/'+s3_file_name)
  File "/home/airflow/.local/lib/python3.9/site-packages/fsspec/asyn.py", line 118, in wrapper
    return sync(self.loop, func, *args, **kwargs)
  File "/home/airflow/.local/lib/python3.9/site-packages/fsspec/asyn.py", line 103, in sync
    raise return_result
  File "/home/airflow/.local/lib/python3.9/site-packages/fsspec/asyn.py", line 56, in _runner
    result[0] = await coro
  File "/home/airflow/.local/lib/python3.9/site-packages/fsspec/asyn.py", line 577, in _put
    trailing_sep(rpath) or await self._isdir(rpath)
  File "/home/airflow/.local/lib/python3.9/site-packages/s3fs/core.py", line 1554, in _isdir
    return bool(await self._lsdir(path))
  File "/home/airflow/.local/lib/python3.9/site-packages/s3fs/core.py", line 768, in _lsdir
    raise translate_boto_error(e)
PermissionError: The AWS Access Key Id you provided does not exist in our records.
[2025-06-29T09:57:53.710+0000] {taskinstance.py:1206} INFO - Marking task as FAILED. dag_id=etl_reddit_pipeline, task_id=s3_upload, run_id=manual__2025-06-29T09:57:44.756224+00:00, execution_date=20250629T095744, start_date=20250629T095751, end_date=20250629T095753
[2025-06-29T09:57:53.726+0000] {standard_task_runner.py:110} ERROR - Failed to execute job 7 for task s3_upload (The AWS Access Key Id you provided does not exist in our records.; 65)
[2025-06-29T09:57:53.753+0000] {local_task_job_runner.py:240} INFO - Task exited with return code 1
[2025-06-29T09:57:53.776+0000] {taskinstance.py:3498} INFO - 0 downstream tasks scheduled from follow-on schedule check
[2025-06-29T09:57:53.778+0000] {local_task_job_runner.py:222} INFO - ::endgroup::
